Workbook

Sheet Instructions
A1: Q2Data — Unified Q2 team workbook (WeBike)
A2: Built from Q1Data. Paste new Workspace reports into yellow cells. Keep Q1 survey sheets as baseline until refreshed.
A4: Sheet | B4: Contents | C4: Decision use
A5: Needs | B5: Customer need scores by segment (from Q1; refresh if new survey) | C5: Brand Judgment / ads
A6: Applications | B6: Use-pattern importance (from Q1) | C6: Brand design / ads tone
A7: Price_WTP | B7: Ideal-brand price ceilings (from Q1) | C7: Pricing frame vs WTP
A8: Market_Potential | B8: 12-mo units by city × segment (from Q1) | C8: Demand / city #2 / capacity
A9: Sales_Channel | B9: Shop vs web posture — AMS + World web LIVE | C9: City #2 + staffing
A10: Stores_Costs | B10: Store/web setup + lease — update open status | C10: Cash / lease burn
A11: Manufacturing | B11: Fixed capacity live + OC / OT helpers | C11: Operating capacity ≤ 24/day
A12: Production_Sim | B12: Produce/demand/stockouts/utilization + printer add summary | C12: Production simulation & fixed capacity plan
A13: Cost_of_Production | B13: Unit cost by volume (Workspace Q2) | C13: Price vs COGS; volume scenarios
A14: Demand_Forecast | B14: Demand = units/SP × people; brand split; this Q + next Q | C14: OC schedule + printer planning + pricing volume
A15: Pricing | B15: Brand list price decision (Hike Bike) | C15: Price vs WTP and unit cost
... A23: Comp_Industry | B23: Industry pay + interactive packages / productivity | C23: Pay > avg; HR estimates

Sheet Needs
A1: Customer Needs — Importance by Segment
A2: Rename labels to match Workspace. Yellow = inputs. Conditional formatting: green ≥110, red <100.
A4: Need / Benefit | B4: Recreation | C4: Mountain | D4: Speed | E4: Max | F4: Rec flag | G4: Mtn flag | H4: Spd flag | I4: Competitor miss risk (H/M/L) | J4: Notes
A5: Colorful | B5: 116 | C5: 120 | D5: 109 | E5: =IF(COUNT(B5:D5)=0,"",MAX(B5:D5)) -> 120 | F5: =IF(B5="","",IF(B5>=110,"IMPORTANT",IF(B5<100,"CAUTION",""))) -> IMPORTANT | G5: =IF(C5="","",IF(C5>=110,"IMPORTANT",IF(C5<100,"CAUTION",""))) -> IMPORTANT | H5: =IF(D5="","",IF(D5>=110,"IMPORTANT",IF(D5<100,"CAUTION","")))
A6: Fits rider's personality | B6: 116 | C6: 113 | D6: 116 | E6: =IF(COUNT(B6:D6)=0,"",MAX(B6:D6)) -> 116 | F6: =IF(B6="","",IF(B6>=110,"IMPORTANT",IF(B6<100,"CAUTION",""))) -> IMPORTANT | G6: =IF(C6="","",IF(C6>=110,"IMPORTANT",IF(C6<100,"CAUTION",""))) -> IMPORTANT | H6: =IF(D6="","",IF(D6>=110,"IMPORTANT",IF(D6<100,"CAUTION",""))) -> IMPORTANT
A7: Simple to use | B7: 121 | C7: 102 | D7: 69 | E7: =IF(COUNT(B7:D7)=0,"",MAX(B7:D7)) -> 121 | F7: =IF(B7="","",IF(B7>=110,"IMPORTANT",IF(B7<100,"CAUTION",""))) -> IMPORTANT | G7: =IF(C7="","",IF(C7>=110,"IMPORTANT",IF(C7<100,"CAUTION",""))) | H7: =IF(D7="","",IF(D7>=110,"IMPORTANT",IF(D7<100,"CAUTION",""))) -> CAUTION
A8: Safety | B8: 121 | C8: 112 | D8: 113 | E8: =IF(COUNT(B8:D8)=0,"",MAX(B8:D8)) -> 121 | F8: =IF(B8="","",IF(B8>=110,"IMPORTANT",IF(B8<100,"CAUTION",""))) -> IMPORTANT | G8: =IF(C8="","",IF(C8>=110,"IMPORTANT",IF(C8<100,"CAUTION",""))) -> IMPORTANT | H8: =IF(D8="","",IF(D8>=110,"IMPORTANT",IF(D8<100,"CAUTION",""))) -> IMPORTANT
A9: Low price point | B9: 117 | C9: 98 | D9: 70 | E9: =IF(COUNT(B9:D9)=0,"",MAX(B9:D9)) -> 117 | F9: =IF(B9="","",IF(B9>=110,"IMPORTANT",IF(B9<100,"CAUTION",""))) -> IMPORTANT | G9: =IF(C9="","",IF(C9>=110,"IMPORTANT",IF(C9<100,"CAUTION",""))) -> CAUTION | H9: =IF(D9="","",IF(D9>=110,"IMPORTANT",IF(D9<100,"CAUTION",""))) -> CAUTION
A10: Sleek | B10: 104 | C10: 83 | D10: 119 | E10: =IF(COUNT(B10:D10)=0,"",MAX(B10:D10)) -> 119 | F10: =IF(B10="","",IF(B10>=110,"IMPORTANT",IF(B10<100,"CAUTION",""))) | G10: =IF(C10="","",IF(C10>=110,"IMPORTANT",IF(C10<100,"CAUTION",""))) -> CAUTION | H10: =IF(D10="","",IF(D10>=110,"IMPORTANT",IF(D10<100,"CAUTION",""))) -> IMPORTANT
A11: Stylish | B11: 111 | C11: 118 | D11: 116 | E11: =IF(COUNT(B11:D11)=0,"",MAX(B11:D11)) -> 118 | F11: =IF(B11="","",IF(B11>=110,"IMPORTANT",IF(B11<100,"CAUTION",""))) -> IMPORTANT | G11: =IF(C11="","",IF(C11>=110,"IMPORTANT",IF(C11<100,"CAUTION",""))) -> IMPORTANT | H11: =IF(D11="","",IF(D11>=110,"IMPORTANT",IF(D11<100,"CAUTION",""))) -> IMPORTANT
A12: Easy to ride | B12: 124 | C12: 100 | D12: 102 | E12: =IF(COUNT(B12:D12)=0,"",MAX(B12:D12)) -> 124 | F12: =IF(B12="","",IF(B12>=110,"IMPORTANT",IF(B12<100,"CAUTION",""))) -> IMPORTANT | G12: =IF(C12="","",IF(C12>=110,"IMPORTANT",IF(C12<100,"CAUTION",""))) | H12: =IF(D12="","",IF(D12>=110,"IMPORTANT",IF(D12<100,"CAUTION","")))
A13: Comfortable | B13: 124 | C13: 95 | D13: 101 | E13: =IF(COUNT(B13:D13)=0,"",MAX(B13:D13)) -> 124 | F13: =IF(B13="","",IF(B13>=110,"IMPORTANT",IF(B13<100,"CAUTION",""))) -> IMPORTANT | G13: =IF(C13="","",IF(C13>=110,"IMPORTANT",IF(C13<100,"CAUTION",""))) -> CAUTION | H13: =IF(D13="","",IF(D13>=110,"IMPORTANT",IF(D13<100,"CAUTION","")))
A14: Soft ride | B14: 115 | C14: 89 | D14: 87 | E14: =IF(COUNT(B14:D14)=0,"",MAX(B14:D14)) -> 115 | F14: =IF(B14="","",IF(B14>=110,"IMPORTANT",IF(B14<100,"CAUTION",""))) -> IMPORTANT | G14: =IF(C14="","",IF(C14>=110,"IMPORTANT",IF(C14<100,"CAUTION",""))) -> CAUTION | H14: =IF(D14="","",IF(D14>=110,"IMPORTANT",IF(D14<100,"CAUTION",""))) -> CAUTION
A15: Repair, parts, support nearby | B15: 119 | C15: 121 | D15: 120 | E15: =IF(COUNT(B15:D15)=0,"",MAX(B15:D15)) -> 121 | F15: =IF(B15="","",IF(B15>=110,"IMPORTANT",IF(B15<100,"CAUTION",""))) -> IMPORTANT | G15: =IF(C15="","",IF(C15>=110,"IMPORTANT",IF(C15<100,"CAUTION",""))) -> IMPORTANT | H15: =IF(D15="","",IF(D15>=110,"IMPORTANT",IF(D15<100,"CAUTION",""))) -> IMPORTANT
A16: Can handle rough terrain | B16: 111 | C16: 128 | D16: 82 | E16: =IF(COUNT(B16:D16)=0,"",MAX(B16:D16)) -> 128 | F16: =IF(B16="","",IF(B16>=110,"IMPORTANT",IF(B16<100,"CAUTION",""))) -> IMPORTANT | G16: =IF(C16="","",IF(C16>=110,"IMPORTANT",IF(C16<100,"CAUTION",""))) -> IMPORTANT | H16: =IF(D16="","",IF(D16>=110,"IMPORTANT",IF(D16<100,"CAUTION",""))) -> CAUTION
... A34: Soften the impact of rough terrain | B34: 116 | C34: 124 | D34: 90 | E34: =IF(COUNT(B34:D34)=0,"",MAX(B34:D34)) -> 124 | F34: =IF(B34="","",IF(B34>=110,"IMPORTANT",IF(B34<100,"CAUTION",""))) -> IMPORTANT | G34: =IF(C34="","",IF(C34>=110,"IMPORTANT",IF(C34<100,"CAUTION",""))) -> IMPORTANT | H34: =IF(D34="","",IF(D34>=110,"IMPORTANT",IF(D34<100,"CAUTION",""))) -> CAUTION
A35: Easy to navigate on web site | B35: 128 | C35: 118 | D35: 123 | E35: =IF(COUNT(B35:D35)=0,"",MAX(B35:D35)) -> 128 | F35: =IF(B35="","",IF(B35>=110,"IMPORTANT",IF(B35<100,"CAUTION",""))) -> IMPORTANT | G35: =IF(C35="","",IF(C35>=110,"IMPORTANT",IF(C35<100,"CAUTION",""))) -> IMPORTANT | H35: =IF(D35="","",IF(D35>=110,"IMPORTANT",IF(D35<100,"CAUTION",""))) -> IMPORTANT | J35: Web focus
A36: Security of my credit card/identity | B36: 135 | C36: 123 | D36: 124 | E36: =IF(COUNT(B36:D36)=0,"",MAX(B36:D36)) -> 135 | F36: =IF(B36="","",IF(B36>=110,"IMPORTANT",IF(B36<100,"CAUTION",""))) -> IMPORTANT | G36: =IF(C36="","",IF(C36>=110,"IMPORTANT",IF(C36<100,"CAUTION",""))) -> IMPORTANT | H36: =IF(D36="","",IF(D36>=110,"IMPORTANT",IF(D36<100,"CAUTION",""))) -> IMPORTANT | J36: Web focus
A37: Likes to buy on the web | B37: 121 | C37: 122 | D37: 114 | E37: =IF(COUNT(B37:D37)=0,"",MAX(B37:D37)) -> 122 | F37: =IF(B37="","",IF(B37>=110,"IMPORTANT",IF(B37<100,"CAUTION",""))) -> IMPORTANT | G37: =IF(C37="","",IF(C37>=110,"IMPORTANT",IF(C37<100,"CAUTION",""))) -> IMPORTANT | H37: =IF(D37="","",IF(D37>=110,"IMPORTANT",IF(D37<100,"CAUTION",""))) -> IMPORTANT | J37: Web focus
A38: Wants human sales reps/support | B38: 133 | C38: 122 | D38: 118 | E38: =IF(COUNT(B38:D38)=0,"",MAX(B38:D38)) -> 133 | F38: =IF(B38="","",IF(B38>=110,"IMPORTANT",IF(B38<100,"CAUTION",""))) -> IMPORTANT | G38: =IF(C38="","",IF(C38>=110,"IMPORTANT",IF(C38<100,"CAUTION",""))) -> IMPORTANT | H38: =IF(D38="","",IF(D38>=110,"IMPORTANT",IF(D38<100,"CAUTION",""))) -> IMPORTANT | J38: Web focus
A39: Able to track my purchase | B39: 119 | C39: 124 | D39: 115 | E39: =IF(COUNT(B39:D39)=0,"",MAX(B39:D39)) -> 124 | F39: =IF(B39="","",IF(B39>=110,"IMPORTANT",IF(B39<100,"CAUTION",""))) -> IMPORTANT | G39: =IF(C39="","",IF(C39>=110,"IMPORTANT",IF(C39<100,"CAUTION",""))) -> IMPORTANT | H39: =IF(D39="","",IF(D39>=110,"IMPORTANT",IF(D39<100,"CAUTION",""))) -> IMPORTANT | J39: Web focus
A40: Easy to make purchase on web | B40: 127 | C40: 113 | D40: 119 | E40: =IF(COUNT(B40:D40)=0,"",MAX(B40:D40)) -> 127 | F40: =IF(B40="","",IF(B40>=110,"IMPORTANT",IF(B40<100,"CAUTION",""))) -> IMPORTANT | G40: =IF(C40="","",IF(C40>=110,"IMPORTANT",IF(C40<100,"CAUTION",""))) -> IMPORTANT | H40: =IF(D40="","",IF(D40>=110,"IMPORTANT",IF(D40<100,"CAUTION",""))) -> IMPORTANT | J40: Web focus
A43: Segment averages | B43: =_xlfn.FLOOR.MATH((IFERROR(AVERAGE(B5:B41),"")*1)) -> 115 | C43: =_xlfn.FLOOR.MATH((IFERROR(AVERAGE(C5:C41),"")*1)) -> 112 | D43: =_xlfn.FLOOR.MATH((IFERROR(AVERAGE(D5:D41),"")*1)) -> 109
A44: Segment averages, excluding web | B44: =_xlfn.FLOOR.MATH(IFERROR(AVERAGE(B5:B34),""),1) -> 112 | C44: =_xlfn.FLOOR.MATH(IFERROR(AVERAGE(C5:C34),""),1) -> 111 | D44: =_xlfn.FLOOR.MATH(IFERROR(AVERAGE(D5:D34),""),1) -> 107
A45: Segment averages, only web | B45: =_xlfn.FLOOR.MATH(IFERROR(AVERAGE(B35:B40),""),1) -> 127 | C45: =_xlfn.FLOOR.MATH(IFERROR(AVERAGE(C35:C40),""),1) -> 120 | D45: =_xlfn.FLOOR.MATH(IFERROR(AVERAGE(D35:D40),""),1) -> 118

Sheet Applications
A1: Applications / Use Patterns — Importance by Segment
A2: ≥110 = must design for | <100 = may hurt appeal if over-emphasized
A4: Application / Use | B4: Recreation | C4: Mountain | D4: Speed | E4: Max | F4: Rec flag | G4: Mtn flag | H4: Spd flag | I4: Component implications | J4: Peer miss risk
A5: Recreation | B5: 129 | C5: 115 | D5: 106 | E5: =IF(COUNT(B5:D5)=0,"",MAX(B5:D5)) -> 129 | F5: =IF(B5="","",IF(B5>=110,"IMPORTANT",IF(B5<100,"CAUTION",""))) -> IMPORTANT | G5: =IF(C5="","",IF(C5>=110,"IMPORTANT",IF(C5<100,"CAUTION",""))) -> IMPORTANT | H5: =IF(D5="","",IF(D5>=110,"IMPORTANT",IF(D5<100,"CAUTION","")))
A6: Exercise | B6: 115 | C6: 118 | D6: 121 | E6: =IF(COUNT(B6:D6)=0,"",MAX(B6:D6)) -> 121 | F6: =IF(B6="","",IF(B6>=110,"IMPORTANT",IF(B6<100,"CAUTION",""))) -> IMPORTANT | G6: =IF(C6="","",IF(C6>=110,"IMPORTANT",IF(C6<100,"CAUTION",""))) -> IMPORTANT | H6: =IF(D6="","",IF(D6>=110,"IMPORTANT",IF(D6<100,"CAUTION",""))) -> IMPORTANT
A7: Relaxation | B7: 122 | C7: 108 | D7: 102 | E7: =IF(COUNT(B7:D7)=0,"",MAX(B7:D7)) -> 122 | F7: =IF(B7="","",IF(B7>=110,"IMPORTANT",IF(B7<100,"CAUTION",""))) -> IMPORTANT | G7: =IF(C7="","",IF(C7>=110,"IMPORTANT",IF(C7<100,"CAUTION",""))) | H7: =IF(D7="","",IF(D7>=110,"IMPORTANT",IF(D7<100,"CAUTION","")))
A8: Fun | B8: 123 | C8: 115 | D8: 102 | E8: =IF(COUNT(B8:D8)=0,"",MAX(B8:D8)) -> 123 | F8: =IF(B8="","",IF(B8>=110,"IMPORTANT",IF(B8<100,"CAUTION",""))) -> IMPORTANT | G8: =IF(C8="","",IF(C8>=110,"IMPORTANT",IF(C8<100,"CAUTION",""))) -> IMPORTANT | H8: =IF(D8="","",IF(D8>=110,"IMPORTANT",IF(D8<100,"CAUTION","")))
A9: Adventure | B9: 112 | C9: 129 | D9: 117 | E9: =IF(COUNT(B9:D9)=0,"",MAX(B9:D9)) -> 129 | F9: =IF(B9="","",IF(B9>=110,"IMPORTANT",IF(B9<100,"CAUTION",""))) -> IMPORTANT | G9: =IF(C9="","",IF(C9>=110,"IMPORTANT",IF(C9<100,"CAUTION",""))) -> IMPORTANT | H9: =IF(D9="","",IF(D9>=110,"IMPORTANT",IF(D9<100,"CAUTION",""))) -> IMPORTANT
A10: Sport | B10: 81 | C10: 115 | D10: 129 | E10: =IF(COUNT(B10:D10)=0,"",MAX(B10:D10)) -> 129 | F10: =IF(B10="","",IF(B10>=110,"IMPORTANT",IF(B10<100,"CAUTION",""))) -> CAUTION | G10: =IF(C10="","",IF(C10>=110,"IMPORTANT",IF(C10<100,"CAUTION",""))) -> IMPORTANT | H10: =IF(D10="","",IF(D10>=110,"IMPORTANT",IF(D10<100,"CAUTION",""))) -> IMPORTANT
A12: Segment averages | B12: =_xlfn.FLOOR.MATH((IFERROR(AVERAGE(B5:B10),"")*1)) -> 113 | C12: =_xlfn.FLOOR.MATH((IFERROR(AVERAGE(C5:C10),"")*1)) -> 116 | D12: =_xlfn.FLOOR.MATH((IFERROR(AVERAGE(D5:D10),"")*1)) -> 112

Sheet Price_WTP
A1: Price Willing to Pay (Ideal Brand Ceiling)
A2: Treat as maximum for ideal brand. Above = fewer entrants. Elasticity unknown until test market.
A4: Segment | B4: WTP (max) | C4: vs Rec | D4: vs Mountain | E4: Price sensitivity note | F4: Peer price-war risk (H/M/L) | G4: Margin opportunity note
A5: Recreation | B5: 1100 | C5: =IF(OR($B$5="",B5=""),"",B5-$B$5) -> 0 | D5: =IF(OR($B$6="",B5=""),"",B5-$B$6) -> -265 | E5: Q1, we expect all target here | F5: H
A6: Mountain | B6: 1365 | C6: =IF(OR($B$5="",B6=""),"",B6-$B$5) -> 265 | D6: =IF(OR($B$6="",B6=""),"",B6-$B$6) -> 0 | E6: Someone might monopolize Q1 | F6: M
A7: Speed | B7: 1580 | C7: =IF(OR($B$5="",B7=""),"",B7-$B$5) -> 480 | D7: =IF(OR($B$6="",B7=""),"",B7-$B$6) -> 215 | E7: Q1, we expect no target here | F7: L
A9: Optional: paste graph / Workspace notes below

Sheet Market_Potential
A1: 12-Month Market Potential (Units)
A2: Potential = P(purchase) × units × # customers. Early quarterly demand usually << annual/4.
A3: See Sales_Channel sheet for shop vs web strategy (linked to these city sizes). First store LOCKED: Amsterdam.
A4: City | B4: Recreation | C4: Mountain | D4: Speed | E4: City Total | F4: Naive Qtr (Total/4) | G4: Likely peer crowding (H/M/L) | H4: Growth-room note
A5: New York City | B5: 5114 | C5: 4757 | D5: 3826 | E5: =IF(COUNT(B5:D5)=0,"",SUM(B5:D5)) -> 13697 | F5: =IF(E5="","",E5/4) -> 3424.25
A6: Rio de Janeiro | B6: 4194 | C6: 3177 | D6: 1942 | E6: =IF(COUNT(B6:D6)=0,"",SUM(B6:D6)) -> 9313 | F6: =IF(E6="","",E6/4) -> 2328.25
A7: Amsterdam | B7: 5468 | C7: 3447 | D7: 3659 | E7: =IF(COUNT(B7:D7)=0,"",SUM(B7:D7)) -> 12574 | F7: =IF(E7="","",E7/4) -> 3143.5
A8: Bangalore | B8: 3491 | C8: 2439 | D8: 2447 | E8: =IF(COUNT(B8:D8)=0,"",SUM(B8:D8)) -> 8377 | F8: =IF(E8="","",E8/4) -> 2094.25
A9: Segment Total | B9: =IF(COUNT(B5:B8)=0,"",SUM(B5:B8)) -> 18267 | C9: =IF(COUNT(C5:C8)=0,"",SUM(C5:C8)) -> 13820 | D9: =IF(COUNT(D5:D8)=0,"",SUM(D5:D8)) -> 11874 | E9: =IF(COUNT(E5:E8)=0,"",SUM(E5:E8)) -> 43961 | F9: =IF(COUNT(F5:F8)=0,"",SUM(F5:F8)) -> 10990.25
A11: Segment share of total potential | B11: =IF(OR(B9="",E9="",E9=0),"",B9/E9) -> 0.4155274 | C11: =IF(OR(C9="",E9="",E9=0),"",C9/E9) -> 0.31436955 | D11: =IF(OR(D9="",E9="",E9=0),"",D9/E9) -> 0.27010305
A13: City rank by total potential (after fill):
A14: 1.
A15: 2.
A16: 3.
A17: 4.

Sheet Sales_Channel
A1: Sales Channel Strategy — connects to Market_Potential
A2: Company-operated shops + web. LIVE for test market: Amsterdam + World web. Schedule city #2 this quarter.
A4: Market size for channel choice (linked to Market_Potential)
A5: City | B5: Recreation | C5: Mountain | D5: Speed | E5: City Total | F5: Locked first store? | G5: Channel note
A6: New York City | B6: =Market_Potential!B5 -> 5114 | C6: =Market_Potential!C5 -> 4757 | D6: =Market_Potential!D5 -> 3826 | E6: =SUM(B6:D6) -> 13697 | F6: No | G6: Largest overall; likely peer crowding
A7: Rio de Janeiro | B7: =Market_Potential!B6 -> 4194 | C7: =Market_Potential!C6 -> 3177 | D7: =Market_Potential!D6 -> 1942 | E7: =SUM(B7:D7) -> 9313 | F7: No | G7: Smaller Speed pool
A8: Amsterdam | B8: =Market_Potential!B7 -> 5468 | C8: =Market_Potential!C7 -> 3447 | D8: =Market_Potential!D7 -> 3659 | E8: =SUM(B8:D8) -> 12574 | F8: YES — Q1 LOCKED | G8: Largest Recreation pool; team lock
A9: Bangalore | B9: =Market_Potential!B8 -> 3491 | C9: =Market_Potential!C8 -> 2439 | D9: =Market_Potential!D8 -> 2447 | E9: =SUM(B9:D9) -> 8377 | F9: No | G9: Smallest overall; cost may be lower
A11: Brick-and-mortar vs Web
A12: Channel | B12: Advantages | C12: Disadvantages | D12: Our Q1 posture
A13: Brick-and-mortar bike shop | B13: Touch/feel/test ride; segment-specialist sales; custom fit; full control of brand/price/ads/sales; no independent-retailer surprises | C13: Expensive to open/run; many details; productivity drop if >~15 display bikes or >~15 salespeople | D13: LOCKED — Amsterdam Q1
A14: Web sales center | B14: One site serves all geos; broader metro reach; multilingual staff; demand beyond one store footprint | C14: No touch/feel; harder phone vs in-person; must wait for customer to find you (ads/SEM); staff wait for calls | D14: LIVE — World Market
A16: Sim decision tips
A17: 1. Both channels are expensive to start together — may open one first, then expand.
A18: 2. Web and stores cannibalize each other → lower productivity per channel; dual channels may still raise TOTAL demand.
A19: 3. Segment preferences differ for web vs store — Rec especially wants humans + web (see Needs).
A20: 4. Must schedule first channel in Q1 (takes a full quarter) to test in Q2.
A21: 5. Recommended: one store for test marketing; add more after learning.
A22: 6. Store ~3,200 sq ft / 300 m²: display ~50%, fitting ~20%, service ~15%, counter/office/storage ~15%. Middle-class area near major road.
A23: 7. POP displays + several bikes; fitting area for custom measurements.
A24: 8. Productivity risk if more than ~15 bikes OR ~15 salespeople in one store.
A26: Web order fulfillment
A27: 1. Daily web orders (dimensions + preferences) → single fabrication facility.
A28: 2. 3D modeling software generates customized frame specs.
... A33: Strategy worksheet (yellow = team inputs)
A34: Question | B34: Team answer | C34: Data link
A35: Primary channel for Q2 test? | B35: Amsterdam brick-and-mortar (LIVE) | C35: Market_Potential
A36: Open web sales center in Q1? | B36: YES — LIVE (World Market) | C36: Needs web scores; cost + cannibalization tips
A37: First-store segment specialist focus? | B37: Mountain primary (Hike Bike) | C37: decisions.md / Q2Data Pricing
A38: Q2–Q4 city order? | C38: NYC, Rio, Bangalore remaining
A39: Dual-channel cannibalization plan? | C39: Sim: total demand may still rise
A40: Store productivity caps (# bikes / # sales)? | C40: Sim guideline: avoid >15 / >15

Sheet Stores_Costs
A1: Sales outlets and web — setup and lease costs
A2: Full quarter to open. LIVE: Amsterdam store + World web. City #2 undecided (NYC candidate).
A4: Brick-and-mortar stores
A5: City | B5: Status | C5: Setup/Close Cost | D5: Quarterly Lease | E5: 12-mo Rec potential | F5: Notes
A6: New York City | B6: closed | C6: 200000 | D6: 62000 | E6: 5114 | F6: Highest setup+lease
A7: Rio de Janeiro | B7: closed | C7: 90000 | D7: 17000 | E7: 4194
A8: Amsterdam | B8: OPEN (Q2 live) | C8: 136000 | D8: 44000 | E8: 5468
A9: Bangalore | B9: closed | C9: 84000 | D9: 13000 | E9: 3491 | F9: Lowest store costs; also fab city
A11: Web sales center
A12: Region | B12: City | C12: Status | D12: Setup/Close Cost | E12: Quarterly Lease | F12: Notes
A13: World Market | B13: OPEN (Q2 live) | C13: closed | D13: 150000 | E13: 60000 | F13: World Market web live; serves all geos
A15: Q1 cash sketch (major outlays only)
A16: Scenario | B16: Printers | C16: Printer $ | D16: AMS setup | E16: Web setup | F16: Total major outlay | G16: Cash left from $1.5M | H16: >= $300k floor?
A17: AMS only + 2 printers | B17: 2 | C17: 480000 | D17: 136000 | E17: 0 | F17: 616000 | G17: 884000 | H17: YES
A18: AMS only + 3 printers | B18: 3 | C18: 720000 | D18: 136000 | E18: 0 | F18: 856000 | G18: 644000 | H18: YES
A19: AMS + web + 2 printers | B19: 2 | C19: 480000 | D19: 136000 | E19: 150000 | F19: 766000 | G19: 734000 | H19: YES
A20: AMS + web + 3 printers | B20: 3 | C20: 720000 | D20: 136000 | E20: 150000 | F20: 1006000 | G20: 494000 | H20: YES
A21: AMS only + 5 printers | B21: 5 | C21: 1200000 | D21: 136000 | E21: 0 | F21: 1336000 | G21: 164000 | H21: NO
A22: AMS + web + 1 printer | B22: 1 | C22: 240000 | D22: 136000 | E22: 150000 | F22: 526000 | G22: 974000 | H22: YES
A25: Ongoing leases once open: AMS $44k/qtr, web $60k/qtr, NYC $62k, Rio $17k, Bangalore store $13k. Confirm in-sim whether lease hits opening quarter or first operating quarter.

Sheet Manufacturing
A1: Manufacturing — Bangalore production facility
A2: Location fixed for all firms: Bangalore (gov incentives). Cannot relocate or add facilities later; can add printers. Airfreight; no inventory; same-quarter fulfillment; shipping cost to firm.
A4: Production math
A5: 1 frame/hour x 8 hrs/day x 5 days/week x 13 weeks/quarter = 520 units/printer/quarter (normal hours)
A6: Operating capacity <= fixed capacity. Turn printers on/off to set operating capacity and staffing.
A8: Fixed capacity options
A9: 3D Printers | B9: Units/Day | C9: Units/Quarter | D9: Capital Investment | E9: Cash after printers* | F9: + Amsterdam $136k | G9: Notes
A10: 0 | B10: 0 | C10: 0 | D10: 0 | E10: 1500000 | F10: 1364000
A11: 1 | B11: 8 | C11: 520 | D11: 240000 | E11: 1260000 | F11: 1124000
A12: 2 | B12: 16 | C12: 1040 | D12: 480000 | E12: 1020000 | F12: 884000 | G12: Common early-test range | H12: This gives us a conservative approach without additional inventory
A13: 3 | B13: 24 | C13: 1560 | D13: 720000 | E13: 780000 | F13: 644000 | G13: Common early-test range | H13: This covers our goals for having extra capacity
A14: 4 | B14: 32 | C14: 2080 | D14: 960000 | E14: 540000 | F14: 404000 | G14: Tight vs $300k floor
A15: 5 | B15: 40 | C15: 2600 | D15: 1200000 | E15: 300000 | F15: 164000 | G15: BREACHES $300k floor with AMS only
A16: 7 | B16: 56 | C16: 3640 | D16: 1680000 | E16: -180000 | F16: -316000 | G16: BREACHES $300k floor with AMS only
A17: 10 | B17: 80 | C17: 5200 | D17: 2400000 | E17: -900000 | F17: -1036000 | G17: BREACHES $300k floor with AMS only
A20: *Assumes Q1 start cash $1,500,000; ignores other Q1 costs. Required floor: Cash+CD >= $300,000.
A21: MARGIN NOTE: We do NOT have sim COGS/contribution margins yet. Earlier 'high margin segment' language used Price Willing to Pay ceilings (Rec $1100 / Mtn $1365 / Speed $1580) as a price-ladder proxy only — NOT proven unit profit.
A22: Process: daily orders with custom specs -> fab -> box/ship airfreight -> store pickup or break-bulk. No inventory at plant; transit <= 2 days.
A24: Operating Capacity (Workspace — Q2)
A25: Fixed capacity available THIS quarter | B25: 24 | C25: units/day
A26: Quarterly fixed capacity (×65) | B26: =B25*65 -> 1560 | C26: 1,560 at full fixed
A28: Demand & productivity inputs
A29: Total forecasted demand (all brands) | B29: =IF(Demand_Forecast!B12="","",Demand_Forecast!B12) -> 0 | C29: from Demand_Forecast
A30: Worker productivity (HR) | B30: 0.7 | C30: Workspace default 70%; sync Comp_Industry when locked
A31: (alias) demand | B31: =B29 -> 0
A32: (alias) productivity | B32: =B30 -> 0.7
A33: Productivity loss pad | B33: =IF(B30="","",1+(1-B30)) -> 1.3 | C33: e.g. 70% → ×1.30
A34: Operating Capacity — Workspace table
A35: Metric | B35: Units per Day | C35: Units per Quarter | D35: Notes
A36: Fixed capacity (previous quarter) | B36: 0 | C36: 0 | D36: Q1: printers not yet online
A37: Operating capacity (previous quarter) | B37: 0 | C37: 0 | D37: Q1: no production
A38: Fixed capacity | B38: =B25 -> 24 | C38: =B25*65 -> 1560 | D38: 24 / day · 1,560 / quarter
A39: Operating capacity ← CHANGEABLE | B39: 0 | C39: =IF(B39="","",B39*65) -> 0 | D39: Cannot exceed fixed 24. Yellow = decision
A40: Effective OC after adjustment for worker productivity | B40: =IF(OR(B39="",B30=""),"",B39*B30) -> 0 | C40: =IF(B40="","",B40*65) -> 0 | D40: Scheduled OC × productivity % (e.g. 10×0.70=7)
A41: Effective OC needed for demand projection | B41: =IF(OR(B29="",B30=""),"",(B29/65)*(1+(1-B30))) -> 0 | C41: =IF(OR(B29="",B30=""),"",B29*(1+(1-B30))) -> 0 | D41: Demand/65 × (1 + productivity loss)
A42: Projected worker productivity [%] | B42: =B30 -> 0.7 | D42: Same as B30
A43: New direct labor cost/unit of operating capacity | D43: Approx from Workspace cost curve
A44: New overhead cost/unit of operating capacity | D44: Falls then flats ~$45–50
A45: Expense to change operating capacity (add to overhead) | B45: 0 | D45: Paste from Workspace if non-zero
A46: Labor + overhead $/unit at scheduled OC | B46: =IF(OR(B43="",B44=""),"",B43+B44)
...

Sheet Production_Sim
A1: Production Simulation (Workspace — Q2)
A2: Reflects linked decisions: Demand_Forecast, Manufacturing OC/OT, Pricing, Cost_of_Production. Yellow = overrides. Re-paste Workspace when live numbers differ. Detail: manufacturing-background.md
A3: Percent of forecasted demand (scenario) | B3: 1 | C3: 100% = use Demand_Forecast; try 50% / 150% scenarios
A5: Brand — Produce / Demand / Price
A6: Brand | B6: Produce (Y/N) | C6: Previous Demand | D6: Projected Demand | E6: Average Cost | F6: Selling Price | G6: Unit Contribution
A7: Hike Bike | B7: Y | C7: 0 | D7: =IF(OR(UPPER(B7)="N",UPPER(B7)="NO"),0,IF(Demand_Forecast!D17="","",Demand_Forecast!D17*$B$3)) -> 0 | E7: =IF(Cost_of_Production!B15="","",Cost_of_Production!B15) -> 924 | F7: =IF(Pricing!F5="","",Pricing!F5) | G7: =IF(OR(F7="",E7=""),"",F7-E7)
A9: Capacity (linked to Manufacturing)
A10: Metric | B10: Units/Day | C10: Units/Quarter
A11: Fixed capacity | B11: =Manufacturing!B25 -> 24 | C11: =Manufacturing!B25*65 -> 1560
A12: Operating capacity | B12: =Manufacturing!B39 -> 0 | C12: =IF(Manufacturing!B39="","",Manufacturing!B39*65) -> 0
A13: Effective OC after productivity (no OT) | B13: =Manufacturing!B40 -> 0 | C13: =Manufacturing!C40 -> 0
A14: Effective OC needed for demand projection | B14: =Manufacturing!B41 -> 0 | C14: =Manufacturing!C41 -> 0
A15: Maximum hours of overtime per day | B15: =Manufacturing!B53 -> 0
A16: Projected worker productivity [%] (base / with OT) | B16: =Manufacturing!B30 -> 0.7 | C16: =Manufacturing!B97 -> 0.7
A18: Number of Units
A19: Brand | B19: Units Produced | C19: Net Demand | D19: Lost Sales Due to Stock-Outs
A20: Hike Bike | B20: =IF(OR(D7="",Manufacturing!B39=""),0,MIN(D7,Manufacturing!B39*IF(Manufacturing!B53=0,Manufacturing!B30,Manufacturing!B97)*65+Manufacturing!B25*(IF(Manufacturing!B53="",0,Manufacturing!B53)/8)*65)) -> 0 | C20: =D7 -> 0 | D20: =IF(OR(C20="",B20=""),0,MAX(0,C20-B20)) -> 0
A21: Total | B21: =B20 -> 0 | C21: =C20 -> 0 | D21: =D20 -> 0
A22: Unmet demand % | B22: =IF(OR(C21="",C21=0),"",D21/C21)
A23: Next-Q ill-will penalty % (½ unmet) | B23: =IF(B22="","",B22/2)
A25: Production Costs per Unit
A26: Brand | B26: Units Produced | C26: Direct Materials | D26: + Direct Labor | E26: + Total Overhead | F26: ="= Production Average" -> = Production Average
A27: Hike Bike | B27: =B20 -> 0 | C27: 337 | D27: =IF(Manufacturing!B43="","",Manufacturing!B43+IF(Manufacturing!B96="",0,Manufacturing!B96)) | E27: =IF(Manufacturing!B44="","",Manufacturing!B44+IF(Manufacturing!B45="",0,Manufacturing!B45)) | F27: =IF(COUNT(C27:E27)<1,"",SUM(C27:E27)) -> 337 | G27: Materials default ~$337 parts (brand-mountain); replace with Workspace
A28: vs Cost_of_Production table | B28: =IF(Cost_of_Production!B15="","",Cost_of_Production!B15) -> 924 | C28: Reconcile F27 vs Workspace volume cost table
A30: Operating Capacity Utilization
A31: Overtime
A32: Overtime hours used | B32: =IF(OR(C20="",Manufacturing!B39=""),0,IF(C20<=Manufacturing!B39*Manufacturing!B30*65,0,MIN(IF(Manufacturing!B53="",0,Manufacturing!B53),(C20-Manufacturing!B39*Manufacturing!B30*65)/(Manufacturing!B25*65/8)))) -> 0 | C32: Approx hours needed; capped by max authorized
A33: Overtime capacity (units/quarter add'l) | B33: =Manufacturing!B94 -> 0
A34: Production worker productivity without overtime | B34: =Manufacturing!B30 -> 0.7
A35: Production worker productivity with overtime | B35: =IF(OR(Manufacturing!B53="",Manufacturing!B53=0),"N/A",Manufacturing!B97) -> N/A
A36: Increase in average direct labor cost/unit due to overtime | B36: =Manufacturing!B96
A38: Operating Capacity
A39: Planned operating capacity (units/quarter) | B39: =IF(Manufacturing!B39="","",Manufacturing!B39*65) -> 0
A40: Planned operating capacity including overtime | B40: =IF(B39="","",B39+IF(B33="",0,B33)) -> 0
A41: Production worker productivity (effective) | B41: =IF(OR(Manufacturing!B53="",Manufacturing!B53=0),Manufacturing!B30,Manufacturing!B97) -> 0.7
A42: Effective operating capacity (units/quarter) | B42: =IF(Manufacturing!B39="","",Manufacturing!B39*IF(Manufacturing!B53=0,Manufacturing!B30,Manufacturing!B97)*65+Manufacturing!B25*(IF(Manufacturing!B53="",0,Manufacturing!B53)/8)*65*IF(Manufacturing!B53=0,1,Manufacturing!B97)) -> 0
A43: Effective operating capacity utilized | B43: =B20 -> 0
A44: Effective operating capacity utilization | B44: =IF(OR(B42="",B42=0),"",B43/B42)
A46: Excess Capacity
A47: Unused operating capacity | B47: =IF(OR(B42="",B43=""),0,MAX(0,B42-B43)) -> 0
...

Sheet Cost_of_Production
A1: Cost of Production Estimate
A2: Report reflects company decisions in Quarter 2 (Workspace). Look under the column for total units you expect to sell across ALL brands.
A3: Ask Sales for the demand forecast. Unit cost falls with volume until crowding near fixed capacity.
A5: Brand | B5: 100 units | C5: 250 units | D5: 500 units | E5: 1,000 units | F5: 5,000 units | G5: 10,000 units
A6: Hike Bike | B6: 924 | C6: 675 | D6: 550 | E6: 495 | F6: 405 | G6: 363
A8: Volume columns (units across all brands) | B8: 100 | C8: 250 | D8: 500 | E8: 1000 | F8: 5000 | G8: 10000
A9: Source | B9: Workspace — Cost of Production Estimate (Q2)
A10: As-of | B10: Q2 current decisions
A12: Lookup helper (yellow = expected total units)
A13: Expected total units (all brands) | B13: =IF(Demand_Forecast!B12="","",Demand_Forecast!B12) -> 0 | C13: linked to Demand_Forecast total (override yellow if needed)
A14: Nearest column volume | B14: =IF(B13="","",IF(B13<=175,100,IF(B13<=375,250,IF(B13<=750,500,IF(B13<=3000,1000,IF(B13<=7500,5000,10000)))))) -> 100
A15: Est. unit production cost (Hike Bike) | B15: =IF(B13="","",IF(B14=100,B6,IF(B14=250,C6,IF(B14=500,D6,IF(B14=1000,E6,IF(B14=5000,F6,G6)))))) -> 924
A16: Note | B16: Interpolation not applied — uses nearest published column. Re-paste table if Workspace updates.
A18: Room for additional brands (paste when priced)
A19: Brand | B19: 100 | C19: 250 | D19: 500 | E19: 1000 | F19: 5000 | G19: 10000

Sheet Demand_Forecast
A1: Demand Projection — Current & Next Quarter
A2: Formula: Demand = units per salesperson × # sales people. Feeds Manufacturing OC / Pricing / Cost_of_Production. Detail: demand-projection-background.md · Yellow = changeable.
A3: Q2 tip: conservative — ~30–70 units/SP; safe ~40. Q3 tip: ~40–80 units/SP; start ~60. Stock-out ill-will: next Q demand cut by half of unmet %.
A5: This Quarter (Projected) vs Last Quarter (Actual)
A6: Channel | B6: Last Q — Sales People | C6: Last Q — Demand/SP | D6: Last Q — Total Demand | E6: This Q — Sales People | F6: This Q — Demand/SP | G6: This Q — Total Demand
A7: Stores | B7: 0 | C7: 0 | D7: 0 | E7: =IF(Sales_Ops!C19="","",Sales_Ops!C19) -> 0 | F7: 40 | G7: =IF(OR(E7="",F7=""),"",E7*F7) -> 0
A8: Web Sales Center | B8: 0 | C8: 0 | D8: 0 | E8: =IF(Sales_Ops!E55="","",Sales_Ops!E55) -> 0 | F8: 40 | G8: =IF(OR(E8="",F8=""),"",E8*F8) -> 0
A9: Total | B9: =B7+B8 -> 0 | D9: =D7+D8 -> 0 | E9: =IF(COUNT(E7:E8)=0,"",SUM(E7:E8)) -> 0 | G9: =IF(COUNT(G7:G8)=0,"",SUM(G7:G8)) -> 0
A10: Scenario multiplier (lean stress-test) | B10: 1 | C10: 1.0 = base; 0.5 = half; 1.5 = +50%
A11: Total forecasted demand (adjusted) — Manufacturing link
A12: Total forecasted demand (adjusted) | B12: =IF(G9="","",G9*B10) -> 0 | C12: ← Manufacturing!B31 and Cost_of_Production lookup use this cell
A13: Changeable this Q: E7/E8 people (linked; override OK) · F7/F8 demand per SP · brand demands below · B10 multiplier
A15: Brand Demand Projections
A16: Brand | B16: Last Q Demand | C16: Last Q % | D16: This Q Demand | E16: This Q % | F16: Capacity Required (units) | G16: Segment | H16: Notes
A17: Hike Bike | B17: n/a | C17: n/a | D17: =IF($B$12="","",$B$12) -> 0 | E17: =IF(OR($B$12="",D17="",$B$12=0),"",D17/$B$12) | F17: =D17 -> 0 | G17: Mountain | H17: Primary; replace D17 formula with fixed units if splitting brands
E18: =IF(OR($B$12="",D18="",$B$12=0),"",D18/$B$12) | F18: =D18 -> 0 | H18: Optional brand 2
E19: =IF(OR($B$12="",D19="",$B$12=0),"",D19/$B$12) | F19: =D19 -> 0 | H19: Optional brand 3
A20: Total | D20: =IF(COUNT(D17:D19)=0,"",SUM(D17:D19)) -> 0 | E20: =IF(OR($B$12="",D20=""),"",D20/$B$12) -> #DIV/0! | F20: =D20 -> 0 | H20: Should equal 100% of B12
A21: Brand sum matches total? | B21: =IF(OR(B12="",D20=""),"",IF(ABS(D20-B12)<0.5,"YES","NO — adjust brand demands")) -> YES
A23: Operating capacity required to satisfy projected demand
B24: Units / Quarter | C24: Units / Day
A25: Operating capacity required (raw demand) | B25: =IF(B12="","",B12) -> 0 | C25: =IF(B12="","",B12/65) -> 0 | D25: Workspace-style: demand ÷ 65 workdays
A26: Min daily OC with productivity pad | B26: =IF(OR(B12="",Manufacturing!B32=""),"",B12) -> 0 | C26: =IF(OR(B12="",Manufacturing!B32=""),"",B12/65*(1+(1-Manufacturing!B32))) -> 0 | D26: Use this when scheduling OC (Manufacturing lecture)
A27: Fixed capacity / day available | C27: =Manufacturing!B25 -> 24
A28: Headroom (fixed − padded daily OC) | C28: =IF(OR(C26="",C27=""),"",C27-C26) -> 24
A30: Demand Projection — Next Quarter (for fixed capacity / printers)
A31: Channel | B31: This Q — Outlets | C31: This Q — People | D31: This Q — Demand/SP | E31: This Q — Total | F31: Next Q — Outlets | G31: Next Q — People | H31: Next Q — Demand/SP | I31: Next Q — Total
A32: Stores | B32: 1 | C32: =E7 -> 0 | D32: =F7 -> 40 | E32: =G7 -> 0 | F32: 1 | H32: 60 | I32: =IF(OR(G32="",H32=""),"",G32*H32)
A33: Web Sales Center | B33: 1 | C33: =E8 -> 0 | D33: =F8 -> 40 | E33: =G8 -> 0 | F33: 1 | H33: 60 | I33: =IF(OR(G33="",H33=""),"",G33*H33)
A34: Total | B34: =B32+B33 -> 2 | C34: =IF(COUNT(C32:C33)=0,"",SUM(C32:C33)) -> 0 | E34: =IF(COUNT(E32:E33)=0,"",SUM(E32:E33)) -> 0 | F34: =F32+F33 -> 2 | G34: =IF(COUNT(G32:G33)=0,"",SUM(G32:G33)) | I34: =IF(COUNT(I32:I33)=0,"",SUM(I32:I33))
A36: Next Q total demand (for printer planning) | B36: =I34 | C36: Link hint: also paste into Sales_Ops Q3 demand / Manufacturing capacity add
A37: Next Q min daily OC (w/ productivity pad) | B37: =IF(OR(I34="",Manufacturing!B32=""),"",I34/65*(1+(1-Manufacturing!B32))) | C37: If > fixed 24/day, order printers this Q
A38: Changeable next Q: F32/F33 outlets · G32/G33 people · H32/H33 demand per SP
A40: Ill-will reminder | B40: Unmet demand % this Q → next Q demand reduced by half that %. Prefer slight OC buffer / overtime safety net over chronic stock-outs.
A41: Source | B41: Workspace — Demand Projection (current + next quarter)

Sheet Pricing
A1: Brand Pricing — Q2
A2: Decide list price for each brand on sale. Compare to WTP ceiling and estimated unit production cost at expected volume.
A4: Brand | B4: Segment | C4: Priority | D4: WTP ceiling | E4: Est. unit prod. cost | F4: List price (decision) | G4: vs WTP | H4: Gross vs prod. cost | I4: Gross margin % | J4: Status
A5: Hike Bike | B5: Mountain | C5: 1 | D5: =Price_WTP!B6 -> 1365 | E5: =Cost_of_Production!B15 -> 924 | G5: =IF(OR(F5="",D5=""),"",F5-D5) | H5: =IF(OR(F5="",E5=""),"",F5-E5) | I5: =IF(OR(F5="",E5="",F5=0),"",H5/F5) | J5: OPEN — set list price
A7: Pricing notes
A8: Mountain WTP ceiling (ideal brand) | B8: =Price_WTP!B6 -> 1365
A9: Alumni ballpark (advisory only) | B9: ~$1,260–$1,500
A10: At 100 units, COGS ≈ $924 → price must clear this + other opex
A11: At 250 units, COGS ≈ $675; at 500 ≈ $550 — volume drops unit cost sharply
A12: Decision tip: price near WTP if Brand/Ad Judgment lead; slightly under if fighting for share
A13: Team decision (yellow F5). Do not lock until majority vote.
A15: Scenario scratch (optional)
A16: Trial price
A17: Assumed volume
A18: Nearest cost column | B18: =IF(B17="","",IF(B17<=175,100,IF(B17<=375,250,IF(B17<=750,500,IF(B17<=3000,1000,IF(B17<=7500,5000,10000))))))
A19: Unit cost at trial volume | B19: =IF(B17="","",IF(B18=100,Cost_of_Production!B6,IF(B18=250,Cost_of_Production!C6,IF(B18=500,Cost_of_Production!D6,IF(B18=1000,Cost_of_Production!E6,IF(B18=5000,Cost_of_Production!F6,Cost_of_Production!G6))))))
A20: Unit contribution (price − cost) | B20: =IF(OR(B16="",B19=""),"",B16-B19)

Sheet Media_Preference
A1: Media Preference
A2: One-time report prepared for your company (Workspace). Higher score = stronger preference for that medium in the segment.
A3: Use to prioritize major media placement for Mountain (primary), then Speed / Rec. Yellow = placement decisions (not locked).
A5: Medium | B5: Recreation | C5: Mountain | D5: Speed | E5: Max | F5: Mtn rank | G5: Notes
A6: Leisure & Entertainment | B6: 143 | C6: 60 | D6: 51 | E6: =IF(COUNT(B6:D6)=0,"",MAX(B6:D6)) -> 143 | F6: =IF(C6="","",RANK(C6,$C$6:$C$12,0)) -> 7
A7: Health & Fitness Magazines | B7: 127 | C7: 104 | D7: 100 | E7: =IF(COUNT(B7:D7)=0,"",MAX(B7:D7)) -> 127 | F7: =IF(C7="","",RANK(C7,$C$6:$C$12,0)) -> 4
A8: Biking Magazines | B8: 51 | C8: 134 | D8: 133 | E8: =IF(COUNT(B8:D8)=0,"",MAX(B8:D8)) -> 134 | F8: =IF(C8="","",RANK(C8,$C$6:$C$12,0)) -> 1
A9: Sport Magazines | B9: 84 | C9: 123 | D9: 117 | E9: =IF(COUNT(B9:D9)=0,"",MAX(B9:D9)) -> 123 | F9: =IF(C9="","",RANK(C9,$C$6:$C$12,0)) -> 2
A10: Business Magazines | B10: 90 | C10: 93 | D10: 125 | E10: =IF(COUNT(B10:D10)=0,"",MAX(B10:D10)) -> 125 | F10: =IF(C10="","",RANK(C10,$C$6:$C$12,0)) -> 6
A11: New Venture Magazines | B11: 81 | C11: 94 | D11: 114 | E11: =IF(COUNT(B11:D11)=0,"",MAX(B11:D11)) -> 114 | F11: =IF(C11="","",RANK(C11,$C$6:$C$12,0)) -> 5
A12: General News Magazines | B12: 111 | C12: 122 | D12: 113 | E12: =IF(COUNT(B12:D12)=0,"",MAX(B12:D12)) -> 122 | F12: =IF(C12="","",RANK(C12,$C$6:$C$12,0)) -> 3
A14: Mountain priority (by score)
A15: 1st | B15: Biking Magazines (134)
A16: 2nd | B16: Sport Magazines (123)
A17: 3rd | B17: General News Magazines (122)
A18: Avoid / low for Mountain | B18: Leisure & Entertainment (60) — Rec-skewed
A20: Speed priority (by score)
A21: 1st | B21: Biking Magazines (133)
A22: 2nd | B22: Business Magazines (125)
A23: 3rd | B23: Sport Magazines (117)
A25: Recreation priority (by score)
A26: 1st | B26: Leisure & Entertainment (143)
A27: 2nd | B27: Health & Fitness Magazines (127)
A28: 3rd | B28: General News Magazines (111)
A30: Major media placement (OPEN — team decision)
A31: Ad name / focus | B31: Primary medium | C31: Inserts / spend | D31: Secondary medium | E31: Inserts / spend | F31: Geo / notes | G31: Status
A32: Hike Bike — Mountain primary | F32: AMS + web audience | G32: OPEN
A33: Secondary segment ad (TBD) | G33: OPEN
A34: Company / corporate ad (optional) | G34: OPEN
A36: Budget / constraints
A37: Total traditional media budget (this Q) | C37: yellow = decision; keep Cash+CD ≥ $300k
A38: Web media / SEM budget (this Q)
A39: Source | B39: Workspace — Media Preference (one-time report)
A40: Guidance | B40: Primary spend should follow Mountain prefs (Biking → Sport → General News). Leisure is Rec-primary — use only if Rec ad launched.

Sheet Web_SEO
A1: Internet Marketing / Organic SEM — Web Pages
A2: Q2: build marketing site from ads; assign segment (keywords follow); check to run. Organic first — slow ramp. Yellow = decisions (not locked). Detail: seo-internet-marketing-background.md
A3: SERP tip: only first 3 ad benefits show in search results — rank carefully. No deceptive claims (match Hike Bike specs).
A5: Background summary
A6: Focus | B6: Organic SEM this quarter; paid SEM later
A7: Content source | B7: Convert media ads → web layout (same message)
A8: Keywords | B8: Agency set per segment — chosen when you pick segment (≠ ad benefits)
A9: Expectation | B9: Modest early traffic; support with traditional ads that list brand + URL
A10: Localize | B10: Pages translated / country-tagged for markets with outlets
A11: Fee | C11: yellow = paste modest web-page design fee from Workspace
A13: Web Page Content tracker (from ads)
A14: Ad name | B14: Brand emphasized | C14: Segment + keywords | D14: Status (Inactive/Run) | E14: SERP top-3 benefits OK? | F14: Deceptive flag? | G14: Design fee | H14: Notes
A15: TBD — Mountain primary ad | B15: Hike Bike | C15: Mountain (agency keywords) | D15: Inactive | H15: Primary; steep-trail / adventure pool
A16: TBD — Secondary segment ad | D16: Inactive | H16: Speed or Rec if launched
A17: TBD — Company ad (optional) | B17: WeBike (company) | D17: Inactive | H17: No brand emphasize
A19: Segment keyword reminder
A20: Segment | B20: Keywords (paste from Workspace when assigned) | C20: Primary use
A21: Mountain | C21: Hike Bike / primary Q2
A22: Speed | C22: If Speed ad/page launched
A23: Recreation | C23: If Rec ad/page launched
A25: Organic support checklist
A26: Traditional ads list brand + web URL | C26: Yes/No — helps discovery
A27: Deceptive review cleared
A28: Cash+CD still ≥ $300k after page fees
A29: Source | B29: Workspace — Internet marketing / Web Page Content / organic SEM
A31: Do not expect
A32: Large Q2 demand from organic alone. Pair with media placement + strong top-3 benefits.

Sheet Sales_Ops
A1: Sales Channel Ops — Staffing Planner + Regional Summary
A2: Plan per-location headcount and specialty training (Service / Recreation / Mountain / Speed). Yellow = inputs. Paste Workspace unit costs into rate table. Test tip: ≤7 people per city; ≥1 service. Detail: sales-channel-background.md
A3: Training counts need not equal total headcount — unassigned sell to all segments equally. Prior Q = 0 (no sales staff in Q1 setup).
A5: Unit cost rates (paste from Workspace — yellow)
A6: Cost item | B6: Unit / basis | C6: $ this quarter | D6: Notes
A7: Hiring expense | B7: per person hired | D7: One-time when headcount rises
A8: Layoff expense | B8: per person laid off | D8: One-time when headcount falls
A9: Salary + training — Service | B9: per person assigned | D9: Specialty training cost
A10: Salary + training — Recreation | B10: per person assigned
A11: Salary + training — Mountain | B11: per person assigned | D11: Primary segment
A12: Salary + training — Speed | B12: per person assigned
A13: Salary + training — Unassigned / general | B13: per unassigned person | D13: No specialty; optional rate
A15: Rate keys (for formulas): Hire=C7 Layoff=C8 Svc=C9 Rec=C10 Mtn=C11 Spd=C12 Unass=C13
A17: Per-location staffing & specialized training
A18: Location | B18: Status | C18: Total sales+service | D18: Service | E18: Recreation | F18: Mountain | G18: Speed | H18: Unassigned (calc) | I18: Specialty sum | J18: ≤7 tip / notes
A19: Amsterdam | B19: OPEN (Q2 live) | C19: 0 | D19: 0 | E19: 0 | F19: 0 | G19: 0 | H19: =IF(C19="","",C19-SUM(D19:G19)) -> 0 | I19: =IF(COUNT(D19:G19)=0,"",SUM(D19:G19)) -> 0 | J19: Physical store — Hike Bike primary
A20: World Web | B20: OPEN (Q2 live) | C20: =IF(E55="","",E55) -> 0 | D20: 0 | E20: 0 | F20: 0 | G20: 0 | H20: =IF(C20="","",C20-SUM(D20:G20)) -> 0 | I20: =IF(COUNT(D20:G20)=0,"",SUM(D20:G20)) -> 0 | J20: Total linked to Web Personnel E55 (C55+D55)
A21: City #2 (next Q) | B21: PLANNING | H21: =IF(C21="","",C21-SUM(D21:G21)) | I21: =IF(COUNT(D21:G21)=0,"",SUM(D21:G21)) | J21: Opens next quarter if scheduled
A22: Other / TBD | B22: — | H22: =IF(C22="","",C22-SUM(D22:G22)) | I22: =IF(COUNT(D22:G22)=0,"",SUM(D22:G22)) | J22: Optional
A23: Checks
A24: AMS total ≤7? | B24: =IF(C19="","",IF(C19<=7,"YES","OVER tip")) -> YES
A25: AMS service ≥1? | B25: =IF(D19="","",IF(D19>=1,"YES","NEED ≥1 service")) -> NEED ≥1 service
A26: Specialty ≤ total (all rows)? | B26: =IF(OR(H19<0,H20<0,IF(C21="",FALSE,H21<0),IF(C22="",FALSE,H22<0)),"ERROR — specialties exceed total","OK") -> OK
A28: Estimated salary & training cost by location (uses rates above)
A29: Location | B29: Service $ | C29: Rec $ | D29: Mountain $ | E29: Speed $ | F29: Unassigned $ + Total
A30: =A19 -> Amsterdam | B30: =IF(OR(D19="",$C$9=""),"",D19*$C$9) | C30: =IF(OR(E19="",$C$10=""),"",E19*$C$10) | D30: =IF(OR(F19="",$C$11=""),"",F19*$C$11) | E30: =IF(OR(G19="",$C$12=""),"",G19*$C$12) | F30: =IF(C19="","",IFERROR(B30,0)+IFERROR(C30,0)+IFERROR(D30,0)+IFERROR(E30,0)+IF(OR(H19="",$C$13=""),0,H19*$C$13)) -> #VALUE!
A31: =A20 -> World Web | B31: =IF(OR(D20="",$C$9=""),"",D20*$C$9) | C31: =IF(OR(E20="",$C$10=""),"",E20*$C$10) | D31: =IF(OR(F20="",$C$11=""),"",F20*$C$11) | E31: =IF(OR(G20="",$C$12=""),"",G20*$C$12) | F31: =IF(C20="","",IFERROR(B31,0)+IFERROR(C31,0)+IFERROR(D31,0)+IFERROR(E31,0)+IF(OR(H20="",$C$13=""),0,H20*$C$13)) -> #VALUE!
A32: =A21 -> City #2 (next Q) | B32: =IF(OR(D21="",$C$9=""),"",D21*$C$9) | C32: =IF(OR(E21="",$C$10=""),"",E21*$C$10) | D32: =IF(OR(F21="",$C$11=""),"",F21*$C$11) | E32: =IF(OR(G21="",$C$12=""),"",G21*$C$12) | F32: =IF(C21="","",IFERROR(B32,0)+IFERROR(C32,0)+IFERROR(D32,0)+IFERROR(E32,0)+IF(OR(H21="",$C$13=""),0,H21*$C$13))
A33: =A22 -> Other / TBD | B33: =IF(OR(D22="",$C$9=""),"",D22*$C$9) | C33: =IF(OR(E22="",$C$10=""),"",E22*$C$10) | D33: =IF(OR(F22="",$C$11=""),"",F22*$C$11) | E33: =IF(OR(G22="",$C$12=""),"",G22*$C$12) | F33: =IF(C22="","",IFERROR(B33,0)+IFERROR(C33,0)+IFERROR(D33,0)+IFERROR(E33,0)+IF(OR(H22="",$C$13=""),0,H22*$C$13))
A34: Total salary & training (all locations) | B34: =IF(COUNT(F30:F33)=0,"",SUM(F30:F33))
A36: Regional Summary (Workspace mirror — strategic planning)
A37: Total Number of Sales and Service People
A38: Prior Quarter | B38: 0 | C38: Q1 had no sales staff
A39: Current Quarter | B39: =IF(COUNT(C19:C22)=0,"",SUM(C19:C22)) -> 0 | C39: Sum of location totals
A40: Net Change | B40: =IF(B39="","",B39-B38) -> 0
A42: Costs This Quarter
A43: Hiring expenses | B43: =IF(OR(B40="",$C$7=""),"",IF(B40>0,B40*$C$7,0)) | C43: Net hires × hiring rate (simple; refine if mix hire/layoff)
A44: Lay off expenses | B44: =IF(OR(B40="",$C$8=""),"",IF(B40<0,ABS(B40)*$C$8,0)) | C44: Net layoffs × layoff rate
A45: Salary and Training Costs | B45: =B34 | C45: From specialty assignments × rates
A46: TOTAL people costs (hire + layoff + salary/training) | B46: =IF(COUNT(B43:B45)=0,"",SUM(B43:B45))
...

Sheet Web_Productivity
A1: Web Productivity — Purchase Probability Tactics
A2: Workspace: Options to Improve the Probability of Purchase. Start this quarter; full effect over a few quarters; diminishing returns on budget. Detail: web-productivity-background.md · Yellow = decisions (not locked).
A3: You can Stop a service anytime. Chart points are approximate read-offs from Workspace graph.
A5: Options to Improve the Probability of Purchase
A6: Activity | B6: Start (Y/N) | C6: Stop (Y/N) | D6: Status | E6: Setup Cost | F6: Quarterly Budget | G6: Est. Potential Improvement % | H6: Setup due this Q? | I6: Cash hit this Q
A7: Toll-free phone number for advising customers in the decision making process and for handling service calls | D7: =IF(OR(UPPER(B7)="Y",UPPER(B7)="YES"),"Active",IF(OR(UPPER(C7)="Y",UPPER(C7)="YES"),"Stopped","—")) -> — | E7: 3000 | F7: 3000 | G7: =IF(OR(D7<>"Active",F7=""),"",IF(F7<=1500,0.22,IF(F7<=4000,0.31,IF(F7<=7500,0.35,IF(F7<=12500,0.415,IF(F7<=17500,0.44,IF(F7<=25000,0.45,0.465))))))) | I7: =IF(D7<>"Active","",IF(OR(UPPER(H7)="Y",UPPER(H7)="YES"),E7+F7,F7))
A8: Continuous upgrading of the product description, pricing, and order entry pages to improve content, visual appeal and navigation | D8: =IF(OR(UPPER(B8)="Y",UPPER(B8)="YES"),"Active",IF(OR(UPPER(C8)="Y",UPPER(C8)="YES"),"Stopped","—")) -> — | E8: 6000 | F8: 6000 | G8: =IF(OR(D8<>"Active",F8=""),"",IF(F8<=1500,0.12,IF(F8<=4000,0.16,IF(F8<=7500,0.185,IF(F8<=12500,0.235,IF(F8<=17500,0.26,IF(F8<=25000,0.275,0.295))))))) | I8: =IF(D8<>"Active","",IF(OR(UPPER(H8)="Y",UPPER(H8)="YES"),E8+F8,F8))
A10: TOTAL web productivity cash this quarter | B10: =IF(COUNT(I7:I8)=0,"",SUM(I7:I8)) | C10: Sum of active tactics (setup if flagged + quarterly budget)
A12: Planning notes
A13: Default Workspace budgets sit on the steep part of both curves (efficient).
A14: Toll-free dominates page upgrades on improvement % at every budget on the chart.
A15: Most incremental gain is earned by ~$10k; $10k→$30k adds only ~5 points.
A16: Effects take a few quarters to fully mature — don’t expect full % in Q2 alone.
A17: Elements that can be changed: Start/Stop · Quarterly Budget · Setup-due flag
A19: Potential Improvement [%] vs Quarterly Budget (approx chart read-off)
A20: Quarterly Budget | B20: Toll-free phone % | C20: Page upgrades %
A21: 0 | B21: 0 | C21: 0
A22: 3000 | B22: 0.31 | C22: 0.16
A23: 5000 | B23: 0.35 | C23: 0.185
A24: 10000 | B24: 0.415 | C24: 0.235
A25: 15000 | B25: 0.44 | C25: 0.26
A26: 20000 | B26: 0.45 | C26: 0.275
A27: 30000 | B27: 0.465 | C27: 0.295
A29: Source | B29: Workspace Web Sales Center + Potential Improvement chart (Q2)
A30: Cash rule | B30: Keep ending Cash+CD ≥ $300,000 after web productivity + personnel + other Q2 spends.

Sheet Needs_Ranked
A1: Needs Snapshot — linked to Needs sheet
A2: After entering scores on Needs, filter each block where Flag = IMPORTANT, or sort Score descending (copy-paste values if needed).
A4: Recreation priorities | E4: Mountain priorities | I4: Speed priorities
A5: Need | B5: Score | C5: Flag | E5: Need | F5: Score | G5: Flag | I5: Need | J5: Score | K5: Flag
A6: =Needs!A5 -> Colorful | B6: =Needs!B5 -> 116 | C6: =Needs!F5 -> IMPORTANT | E6: =Needs!A5 -> Colorful | F6: =Needs!C5 -> 120 | G6: =Needs!G5 -> IMPORTANT | I6: =Needs!A5 -> Colorful | J6: =Needs!D5 -> 109 | K6: =Needs!H5
A7: =Needs!A6 -> Fits rider's personality | B7: =Needs!B6 -> 116 | C7: =Needs!F6 -> IMPORTANT | E7: =Needs!A6 -> Fits rider's personality | F7: =Needs!C6 -> 113 | G7: =Needs!G6 -> IMPORTANT | I7: =Needs!A6 -> Fits rider's personality | J7: =Needs!D6 -> 116 | K7: =Needs!H6 -> IMPORTANT
A8: =Needs!A7 -> Simple to use | B8: =Needs!B7 -> 121 | C8: =Needs!F7 -> IMPORTANT | E8: =Needs!A7 -> Simple to use | F8: =Needs!C7 -> 102 | G8: =Needs!G7 | I8: =Needs!A7 -> Simple to use | J8: =Needs!D7 -> 69 | K8: =Needs!H7 -> CAUTION
A9: =Needs!A8 -> Safety | B9: =Needs!B8 -> 121 | C9: =Needs!F8 -> IMPORTANT | E9: =Needs!A8 -> Safety | F9: =Needs!C8 -> 112 | G9: =Needs!G8 -> IMPORTANT | I9: =Needs!A8 -> Safety | J9: =Needs!D8 -> 113 | K9: =Needs!H8 -> IMPORTANT
A10: =Needs!A9 -> Low price point | B10: =Needs!B9 -> 117 | C10: =Needs!F9 -> IMPORTANT | E10: =Needs!A9 -> Low price point | F10: =Needs!C9 -> 98 | G10: =Needs!G9 -> CAUTION | I10: =Needs!A9 -> Low price point | J10: =Needs!D9 -> 70 | K10: =Needs!H9 -> CAUTION
A11: =Needs!A10 -> Sleek | B11: =Needs!B10 -> 104 | C11: =Needs!F10 | E11: =Needs!A10 -> Sleek | F11: =Needs!C10 -> 83 | G11: =Needs!G10 -> CAUTION | I11: =Needs!A10 -> Sleek | J11: =Needs!D10 -> 119 | K11: =Needs!H10 -> IMPORTANT
A12: =Needs!A11 -> Stylish | B12: =Needs!B11 -> 111 | C12: =Needs!F11 -> IMPORTANT | E12: =Needs!A11 -> Stylish | F12: =Needs!C11 -> 118 | G12: =Needs!G11 -> IMPORTANT | I12: =Needs!A11 -> Stylish | J12: =Needs!D11 -> 116 | K12: =Needs!H11 -> IMPORTANT
A13: =Needs!A12 -> Easy to ride | B13: =Needs!B12 -> 124 | C13: =Needs!F12 -> IMPORTANT | E13: =Needs!A12 -> Easy to ride | F13: =Needs!C12 -> 100 | G13: =Needs!G12 | I13: =Needs!A12 -> Easy to ride | J13: =Needs!D12 -> 102 | K13: =Needs!H12
A14: =Needs!A13 -> Comfortable | B14: =Needs!B13 -> 124 | C14: =Needs!F13 -> IMPORTANT | E14: =Needs!A13 -> Comfortable | F14: =Needs!C13 -> 95 | G14: =Needs!G13 -> CAUTION | I14: =Needs!A13 -> Comfortable | J14: =Needs!D13 -> 101 | K14: =Needs!H13
A15: =Needs!A14 -> Soft ride | B15: =Needs!B14 -> 115 | C15: =Needs!F14 -> IMPORTANT | E15: =Needs!A14 -> Soft ride | F15: =Needs!C14 -> 89 | G15: =Needs!G14 -> CAUTION | I15: =Needs!A14 -> Soft ride | J15: =Needs!D14 -> 87 | K15: =Needs!H14 -> CAUTION
A16: =Needs!A15 -> Repair, parts, support nearby | B16: =Needs!B15 -> 119 | C16: =Needs!F15 -> IMPORTANT | E16: =Needs!A15 -> Repair, parts, support nearby | F16: =Needs!C15 -> 121 | G16: =Needs!G15 -> IMPORTANT | I16: =Needs!A15 -> Repair, parts, support nearby | J16: =Needs!D15 -> 120 | K16: =Needs!H15 -> IMPORTANT
A17: =Needs!A16 -> Can handle rough terrain | B17: =Needs!B16 -> 111 | C17: =Needs!F16 -> IMPORTANT | E17: =Needs!A16 -> Can handle rough terrain | F17: =Needs!C16 -> 128 | G17: =Needs!G16 -> IMPORTANT | I17: =Needs!A16 -> Can handle rough terrain | J17: =Needs!D16 -> 82 | K17: =Needs!H16 -> CAUTION
... A41: =Needs!A40 -> Easy to make purchase on web | B41: =Needs!B40 -> 127 | C41: =Needs!F40 -> IMPORTANT | E41: =Needs!A40 -> Easy to make purchase on web | F41: =Needs!C40 -> 113 | G41: =Needs!G40 -> IMPORTANT | I41: =Needs!A40 -> Easy to make purchase on web | J41: =Needs!D40 -> 119 | K41: =Needs!H40 -> IMPORTANT

Sheet Growth_Room
A1: Growth Room vs Classmates (1–5 scores)
A2: Gap index = Attractiveness + Serveability − Crowding (higher = more room for growth). Yellow = inputs.
A4: Segment | B4: City / Channel | C4: Attractiveness (1–5) | D4: Expected crowding (1–5) | E4: Our serveability (1–5) | F4: Gap index | G4: Why peers may leave it | H4: Priority (H/M/L)
A5: Recreation | B5: New York | F5: =IF(COUNT(C5:E5)<3,"",C5+E5-D5)
A6: Recreation | B6: Amsterdam | F6: =IF(COUNT(C6:E6)<3,"",C6+E6-D6)
A7: Recreation | B7: Rio de Janeiro | F7: =IF(COUNT(C7:E7)<3,"",C7+E7-D7)
A8: Recreation | B8: Bangalore | F8: =IF(COUNT(C8:E8)<3,"",C8+E8-D8)
A9: Recreation | B9: Web | F9: =IF(COUNT(C9:E9)<3,"",C9+E9-D9)
A10: Mountain | B10: New York | F10: =IF(COUNT(C10:E10)<3,"",C10+E10-D10)
A11: Mountain | B11: Amsterdam | C11: 5 | F11: =IF(COUNT(C11:E11)<3,"",C11+E11-D11)
A12: Mountain | B12: Rio de Janeiro | F12: =IF(COUNT(C12:E12)<3,"",C12+E12-D12)
A13: Mountain | B13: Bangalore | F13: =IF(COUNT(C13:E13)<3,"",C13+E13-D13)
A14: Mountain | B14: Web | C14: 5 | F14: =IF(COUNT(C14:E14)<3,"",C14+E14-D14)
A15: Speed | B15: New York | F15: =IF(COUNT(C15:E15)<3,"",C15+E15-D15)
A16: Speed | B16: Amsterdam | F16: =IF(COUNT(C16:E16)<3,"",C16+E16-D16)
A17: Speed | B17: Rio de Janeiro | F17: =IF(COUNT(C17:E17)<3,"",C17+E17-D17)
A18: Speed | B18: Bangalore | F18: =IF(COUNT(C18:E18)<3,"",C18+E18-D18)
A19: Speed | B19: Web | F19: =IF(COUNT(C19:E19)<3,"",C19+E19-D19)

Sheet Competitor_CI
A1: Competitor (Classmate) Tracker
A2: Q2+: enter firm names and metrics from results / purchased research. Competitor-first buy priority.
A4: Firm | B4: Quarter | C4: Segments | D4: Cities / Web | E4: Brand Judgment notes | F4: Ad Judgment notes | G4: Price posture | H4: Share / demand served | I4: Weakness / gap for us | J4: Our response
A27: Research purchase log (competitor-first)
A28: Quarter | B28: Report bought | C28: Cost | D28: Key competitor insight | E28: Action

Sheet Comp_Industry
A1: Compensation & Productivity Planner (Q2)
A2: Team goal: pay ABOVE average. Interactive planning: try packages → estimate productivity. Importance early: Salary → Health → Vacation → Pension. Detail: compensation-background.md
A3: Projected productivity starts ~70%. Last-quarter industry averages appear from Q3. Yellow = our decisions (not locked).
A4: Sales people
A5: Component | B5: Industry setting | C5: Cost | D5: Importance of further improvement
A6: Salary | B6: 17000 | C6: 17000 | D6: 87
A7: Health benefits | B7: Minimum | C7: 1700 | D7: 84
A8: Vacation | B8: 1 week | C8: 440 | D8: 72
A9: Pension | B9: 1% | C9: 170 | D9: 70
A10: TOTAL yearly cost | C10: 19310
A13: Production workers
A14: Component | B14: Industry setting | C14: Cost | D14: Importance of further improvement
A15: Salary | B15: 14000 | C15: 14000 | D15: 87
A16: Health benefits | B16: Minimum | C16: 1400 | D16: 84
A17: Vacation | B17: 1 week | C17: 363 | D17: 72
A18: Pension | B18: 2% | C18: 280 | D18: 70
A19: TOTAL yearly cost | C19: 16043
A22: Benefit cost menus — Sales (Workspace)
A23: Health tier | B23: Cost | C23: Vacation weeks | D23: Cost | E23: Pension | F23: Total cost | G23: vs Industry
A24: No health benefits | B24: 0 | C24: 0 | D24: 0
A25: Minimum | B25: 1700 | C25: 1 | D25: 440
A26: Expanded | B26: 2550 | C26: 2 | D26: 944
A27: Full coverage | B27: 3740 | C27: 3 | D27: 1475
A28: Comprehensive | B28: 5610 | C28: 4 | D28: 2024
C29: 5 | D29: 2587
C30: 6 | D30: 3161
C31: 7 | D31: 3745
A33: Note: Production health/vacation $ may differ — confirm in Workspace (Q1 ind. Min health $1,400 / 1 wk $363).
A34: Pension cost = Salary × (Pension % / 100). Salary $ = cost $.
A36: OUR SALES PACKAGE (interactive — yellow)
A37: Metric | B37: Our choice | C37: Cost $ | D37: Industry | E37: vs Industry $ | F37: Importance
A38: Annual salary | C38: =IF(B38="","",B38) | D38: 17000 | E38: =IF(C38="","",C38-D38) | F38: 87
A39: Health (type tier name or paste cost) | D39: 1700 | E39: =IF(C39="","",C39-D39) | F39: 84
A40: Vacation weeks | D40: 440 | E40: =IF(C40="","",C40-D40) | F40: 72
A41: Pension % | C41: =IF(OR(B38="",B41=""),"",B38*B41/100) | D41: 170 | E41: =IF(C41="","",C41-D41) | F41: 70
A42: TOTAL yearly cost / person | C42: =IF(COUNT(C38:C41)<1,"",SUM(C38:C41)) | D42: 19310 | E42: =IF(C42="","",C42-D42)
A43: Estimated sales productivity % | B43: 0.7 | C43: Norm ~70%; raise if package clearly above industry / peers
A44: Above industry total? | B44: =IF(C42="","",IF(C42>D42,"YES — goal direction","NO — below/at industry"))
A46: OUR PRODUCTION PACKAGE (interactive — yellow)
A47: Metric | B47: Our choice | C47: Cost $ | D47: Industry | E47: vs Industry $ | F47: Importance
...
